<mujoco model="table_tennis_scene">
  <compiler angle="radian" meshdir="meshes" autolimits="true"/>

  <option timestep="0.001" integrator="implicitfast" iterations="100" solver="Newton" tolerance="1e-10">
    <flag gravity="enable" contact="enable"/>
  </option>

  <visual>
    <headlight diffuse="0.6 0.6 0.6" ambient="0.3 0.3 0.3" specular="0 0 0"/>
    <rgba haze="0.15 0.25 0.35 1"/>
    <quality shadowsize="4096"/>
    <map stiffness="100" shadowscale="0.5" fogstart="10" fogend="15" zfar="50"/>
    <scale forcewidth="0.05" contactwidth="0.2" contactheight="0.05" connect="0.2" com="0.3" camera="0.5" light="0.5" selectpoint="0.05" jointlength="0.5" jointwidth="0.1" actuatorlength="0.5" actuatorwidth="0.2"/>
  </visual>
  
  <asset>
    <!-- FR3 Robot Meshes -->
    <mesh name="link0_mesh" file="link0.stl"/>
    <mesh name="link1_mesh" file="link1.stl"/>
    <mesh name="link2_mesh" file="link2.stl"/>
    <mesh name="link3_mesh" file="link3.stl"/>
    <mesh name="link4_mesh" file="link4.stl"/>
    <mesh name="link5_mesh" file="link5.stl"/>
    <mesh name="link6_mesh" file="link6.stl"/>
    <mesh name="link7_mesh" file="link7.stl"/>
    <mesh name="paddle_mesh" file="table_tennis_racket.stl" scale="0.0023 0.0023 0.0023"/>
    
    <!-- Materials -->
    <material name="robot_white" rgba="0.9 0.9 0.9 1"/>
    <material name="robot_gray" rgba="0.5 0.5 0.5 1"/>
    <material name="paddle_red" rgba="0.8 0.1 0.1 1"/>
    <material name="table_blue" rgba="0.15 0.25 0.6 1"/>
    <material name="table_dark" rgba="0.1 0.1 0.1 1"/>
    <material name="net_black" rgba="0.05 0.05 0.05 1"/>
    <material name="ball_white" rgba="1 1 1 1"/>
    <material name="floor_mat" rgba="0.4 0.4 0.4 1"/>
    <texture name="floor_tex" type="2d" builtin="checker" rgb1="0.3 0.3 0.3" rgb2="0.4 0.4 0.4" width="512" height="512" mark="edge" markrgb="0.5 0.5 0.5"/>
    <material name="floor_mat_tex" texture="floor_tex" texrepeat="10 10" specular="0.1" shininess="0.1"/>
  </asset>
  
  <worldbody>
    <!-- Lighting -->
    <light name="top_light" pos="0 0 4" dir="0 0 -1" diffuse="0.8 0.8 0.8" specular="0.3 0.3 0.3" directional="false" castshadow="true"/>
    <light name="side_light_1" pos="3 0 2" dir="-1 0 -0.5" diffuse="0.5 0.5 0.5" specular="0.1 0.1 0.1"/>
    <light name="side_light_2" pos="-3 0 2" dir="1 0 -0.5" diffuse="0.5 0.5 0.5" specular="0.1 0.1 0.1"/>
    
    <!-- Ground plane -->
    <geom name="floor" type="plane" size="10 10 0.1" material="floor_mat_tex" friction="0.8 0.005 0.0001" solref="0.002 1.0" solimp="0.90 0.95 0.001" condim="4"/>
    
    <!-- TABLE TENNIS TABLE -->
    <body name="table" pos="0 0 0.76">
      <geom name="table_top" type="box" size="1.37 0.7625 0.0125" pos="0 0 0" friction="0.45 0.005 0.0001" solref="0.001 1.0" solimp="0.999 0.999 0.001" condim="4" material="table_blue" mass="50" contype="1" conaffinity="1"/>
      <geom name="center_line" type="box" size="1.37 0.001 0.0126" pos="0 0 0" rgba="1 1 1 1" contype="0" conaffinity="0"/>
      <geom name="end_line_1" type="box" size="0.001 0.7625 0.0126" pos="1.37 0 0" rgba="1 1 1 1" contype="0" conaffinity="0"/>
      <geom name="end_line_2" type="box" size="0.001 0.7625 0.0126" pos="-1.37 0 0" rgba="1 1 1 1" contype="0" conaffinity="0"/>
      <geom name="side_line_1" type="box" size="1.37 0.001 0.0126" pos="0 0.7625 0" rgba="1 1 1 1" contype="0" conaffinity="0"/>
      <geom name="side_line_2" type="box" size="1.37 0.001 0.0126" pos="0 -0.7625 0" rgba="1 1 1 1" contype="0" conaffinity="0"/>
      
      <!-- Net with capsule mesh.  Net body origin sits AT the table top surface
           (pos z=0.0125 = table_top half-thickness in table-body frame), so that:
             world z of net bottom = 0.76 + 0.0125 = 0.7725 m  (table surface)
             world z of net top    = 0.7725 + 0.1525 = 0.9250 m  (standard 15.25 cm height)
      -->
      <body name="net" pos="0 0 0.0125">
        <!-- Vertical net strands (visual only) -->
        <geom name="net_v0" type="capsule" size="0.0008" fromto="0 -0.915 0 0 -0.915 0.1525" material="net_black" contype="0" conaffinity="0"/>
        <geom name="net_v1" type="capsule" size="0.0008" fromto="0 -0.76 0 0 -0.76 0.1525" material="net_black" contype="0" conaffinity="0"/>
        <geom name="net_v2" type="capsule" size="0.0008" fromto="0 -0.61 0 0 -0.61 0.1525" material="net_black" contype="0" conaffinity="0"/>
        <geom name="net_v3" type="capsule" size="0.0008" fromto="0 -0.46 0 0 -0.46 0.1525" material="net_black" contype="0" conaffinity="0"/>
        <geom name="net_v4" type="capsule" size="0.0008" fromto="0 -0.305 0 0 -0.305 0.1525" material="net_black" contype="0" conaffinity="0"/>
        <geom name="net_v5" type="capsule" size="0.0008" fromto="0 -0.15 0 0 -0.15 0.1525" material="net_black" contype="0" conaffinity="0"/>
        <geom name="net_v6" type="capsule" size="0.0008" fromto="0 0 0 0 0 0.1525" material="net_black" contype="0" conaffinity="0"/>
        <geom name="net_v7" type="capsule" size="0.0008" fromto="0 0.15 0 0 0.15 0.1525" material="net_black" contype="0" conaffinity="0"/>
        <geom name="net_v8" type="capsule" size="0.0008" fromto="0 0.305 0 0 0.305 0.1525" material="net_black" contype="0" conaffinity="0"/>
        <geom name="net_v9" type="capsule" size="0.0008" fromto="0 0.46 0 0 0.46 0.1525" material="net_black" contype="0" conaffinity="0"/>
        <geom name="net_v10" type="capsule" size="0.0008" fromto="0 0.61 0 0 0.61 0.1525" material="net_black" contype="0" conaffinity="0"/>
        <geom name="net_v11" type="capsule" size="0.0008" fromto="0 0.76 0 0 0.76 0.1525" material="net_black" contype="0" conaffinity="0"/>
        <geom name="net_v12" type="capsule" size="0.0008" fromto="0 0.915 0 0 0.915 0.1525" material="net_black" contype="0" conaffinity="0"/>
        
        <!-- Horizontal net strands (visual only) -->
        <geom name="net_h0" type="capsule" size="0.0008" fromto="0 -0.915 0.02 0 0.915 0.02" material="net_black" contype="0" conaffinity="0"/>
        <geom name="net_h1" type="capsule" size="0.0008" fromto="0 -0.915 0.04 0 0.915 0.04" material="net_black" contype="0" conaffinity="0"/>
        <geom name="net_h2" type="capsule" size="0.0008" fromto="0 -0.915 0.06 0 0.915 0.06" material="net_black" contype="0" conaffinity="0"/>
        <geom name="net_h3" type="capsule" size="0.0008" fromto="0 -0.915 0.08 0 0.915 0.08" material="net_black" contype="0" conaffinity="0"/>
        <geom name="net_h4" type="capsule" size="0.0008" fromto="0 -0.915 0.10 0 0.915 0.10" material="net_black" contype="0" conaffinity="0"/>
        <geom name="net_h5" type="capsule" size="0.0008" fromto="0 -0.915 0.12 0 0.915 0.12" material="net_black" contype="0" conaffinity="0"/>
        <geom name="net_h6" type="capsule" size="0.0008" fromto="0 -0.915 0.14 0 0.915 0.14" material="net_black" contype="0" conaffinity="0"/>
        <geom name="net_h7" type="capsule" size="0.0015" fromto="0 -0.915 0.1525 0 0.915 0.1525" material="net_black" contype="0" conaffinity="0"/>
        
        <!-- Collision geometries for net -->
        <geom name="net_collision" type="box" size="0.01 0.915 0.07625" pos="0 0 0.07625" friction="0.5 0.005 0.0001" solref="0.003 0.8" solimp="0.75 0.95 0.001" condim="4" contype="1" conaffinity="1" rgba="0.05 0.05 0.05 0.2"/>
        <!-- Top edge as capsule to prevent ball from resting on it -->
        <geom name="net_top_edge" type="capsule" size="0.008" fromto="0 -0.915 0.1525 0 0.915 0.1525" friction="0.3 0.005 0.0001" solref="0.002 0.5" solimp="0.7 0.9 0.001" condim="4" contype="1" conaffinity="1" rgba="0.05 0.05 0.05 0.3"/>
        
        <!-- Net posts (visual only) -->
        <geom name="net_post_1" type="cylinder" size="0.01 0.08625" pos="0 0.925 0" material="table_dark" mass="0.2" contype="0" conaffinity="0"/>
        <geom name="net_post_2" type="cylinder" size="0.01 0.08625" pos="0 -0.925 0" material="table_dark" mass="0.2" contype="0" conaffinity="0"/>
        <geom name="net_tape" type="box" size="0.006 0.915 0.008" pos="0 0 0.07625" rgba="1 1 1 1" contype="0" conaffinity="0"/>
      </body>
      
      <!-- Table legs -->
      <geom name="leg_1" type="box" size="0.025 0.025 0.38" pos="1.2 0.65 -0.38" material="table_dark" mass="2"/>
      <geom name="leg_2" type="box" size="0.025 0.025 0.38" pos="1.2 -0.65 -0.38" material="table_dark" mass="2"/>
      <geom name="leg_3" type="box" size="0.025 0.025 0.38" pos="-1.2 0.65 -0.38" material="table_dark" mass="2"/>
      <geom name="leg_4" type="box" size="0.025 0.025 0.38" pos="-1.2 -0.65 -0.38" material="table_dark" mass="2"/>
      <geom name="frame_long_1" type="box" size="1.2 0.02 0.02" pos="0 0.65 -0.38" material="table_dark" mass="1"/>
      <geom name="frame_long_2" type="box" size="1.2 0.02 0.02" pos="0 -0.65 -0.38" material="table_dark" mass="1"/>
      <geom name="frame_short_1" type="box" size="0.02 0.65 0.02" pos="1.2 0 -0.38" material="table_dark" mass="0.5"/>
      <geom name="frame_short_2" type="box" size="0.02 0.65 0.02" pos="-1.2 0 -0.38" material="table_dark" mass="0.5"/>
    </body>
    
    <!-- FRANKA FR3 ROBOT -->
    <body name="fr3_link0" pos="1.5 0 0.76" quat="0 0 0 1">
      <inertial pos="-0.0172 0.0004 0.0745" mass="2.3966" diaginertia="0.009 0.0115 0.0085"/>
      <geom type="mesh" mesh="link0_mesh" material="robot_white" contype="0" conaffinity="0" group="0"/>
      <body name="fr3_link1" pos="0 0 0.333">
        <inertial pos="0.0003 -0.0272 0.0618" mass="2.7409" diaginertia="0.01 0.0087 0.0099"/>
        <joint name="fr3_joint1" type="hinge" axis="0 0 1" range="-2.9007 2.9007" damping="1" frictionloss="0.1"/>
        <geom type="mesh" mesh="link1_mesh" material="robot_white" contype="0" conaffinity="0" group="0"/>
        <body name="fr3_link2" pos="0 0 0" quat="0.707107 -0.707107 0 0">
          <inertial pos="-0.0006 0.0503 0.0691" mass="2.7402" diaginertia="0.01 0.0098 0.0088"/>
          <joint name="fr3_joint2" type="hinge" axis="0 0 1" range="-1.8326 1.8326" damping="1" frictionloss="0.1"/>
          <geom type="mesh" mesh="link2_mesh" material="robot_white" contype="0" conaffinity="0" group="0"/>
          <body name="fr3_link3" pos="0 -0.316 0" quat="0.707107 0.707107 0 0">
            <inertial pos="0.0269 0.0387 -0.0738" mass="2.3883" diaginertia="0.0079 0.0068 0.0073"/>
            <joint name="fr3_joint3" type="hinge" axis="0 0 1" range="-2.9007 2.9007" damping="1" frictionloss="0.1"/>
            <geom type="mesh" mesh="link3_mesh" material="robot_white" contype="0" conaffinity="0" group="0"/>
            <body name="fr3_link4" pos="0.0825 0 0" quat="0.707107 0.707107 0 0">
              <inertial pos="-0.0532 0.0459 0.0227" mass="2.3883" diaginertia="0.0079 0.0068 0.0073"/>
              <joint name="fr3_joint4" type="hinge" axis="0 0 1" range="-3.0718 -0.0698" damping="1" frictionloss="0.1"/>
              <geom type="mesh" mesh="link4_mesh" material="robot_white" contype="0" conaffinity="0" group="0"/>
              <body name="fr3_link5" pos="-0.0825 0.384 0" quat="0.707107 -0.707107 0 0">
                <inertial pos="0.0001 -0.0614 0.0304" mass="2.7337" diaginertia="0.0136 0.0114 0.0049"/>
                <joint name="fr3_joint5" type="hinge" axis="0 0 1" range="-2.8774 2.8774" damping="0.5" frictionloss="0.1"/>
                <geom type="mesh" mesh="link5_mesh" material="robot_white" contype="0" conaffinity="0" group="0"/>
                <body name="fr3_link6" pos="0 0 0" quat="0.707107 0.707107 0 0">
                  <inertial pos="0.0511 0.0094 0.0009" mass="1.6667" diaginertia="0.0024 0.0021 0.0021"/>
                  <joint name="fr3_joint6" type="hinge" axis="0 0 1" range="-0.0175 3.7525" damping="0.5" frictionloss="0.1"/>
                  <geom type="mesh" mesh="link6_mesh" material="robot_white" contype="0" conaffinity="0" group="0"/>
                  <body name="fr3_link7" pos="0.088 0 0" quat="0.707107 0.707107 0 0">
                    <inertial pos="0.0099 0.0099 0.0235" mass="0.7355" fullinertia="0.0015 0.0014 0.0005 0.0001 0.0001 0.0001"/>
                    <joint name="fr3_joint7" type="hinge" axis="0 0 1" range="-3.0543 3.0543" damping="0.5" frictionloss="0.1"/>
                    <geom type="mesh" mesh="link7_mesh" contype="0" conaffinity="0" group="0"/>
                    <body name="fr3_link8" pos="0 0 0.107">
                      <inertial pos="0 0 0" mass="0.01" diaginertia="0.001 0.001 0.001"/>
                      <body name="paddle" pos="0 0 0.157" quat="1 0 0 0">
                        <inertial pos="0 0 0" mass="0.09" fullinertia="0.0002 0.0002 0.00005 0 0 0"/>
                        <!-- <geom type="mesh" mesh="paddle_mesh" pos="0 0 -0.05" quat="0.707107 0 0.707107 0" material="paddle_red" contype="1" conaffinity="1" group="0"/> -->
                        <!-- euler="1.5708 0 0" = Rx(90°): maps STL-Y (long axis, handle at -Y)
                             to body-Z so the handle points toward link7 (body -Z direction).
                             STL-Z (blade face normal) maps to body -Y, so face normal = body -Y. -->
                        <geom type="mesh" mesh="paddle_mesh" pos="0 0 0" euler="1.5708 0 0" material="paddle_red" contype="0" conaffinity="0" group="0"/>
                        <!-- Blade box: thin in Y (= face-normal direction, body -Y).
                             Z extent covers blade impact area along arm axis. -->
                        <geom name="paddle_blade" type="box" size="0.0785 0.00325 0.076" pos="0 0 0" friction="0.8 0.005 0.0001" contype="1" conaffinity="1" group="3" rgba="0.8 0.1 0.1 0.8"/>
                        <geom name="paddle_handle" type="cylinder" size="0.0125 0.05" pos="0 0 -0.075" friction="0.8 0.005 0.0001" contype="1" conaffinity="1" group="3" rgba="0.6 0.4 0.2 1"/>
                        <site name="paddle_contact" pos="0 0 0" size="0.01" rgba="0 1 0 0.3"/>
                        <!-- paddle_normal is 1 cm in body -Y: face normal = body -Y direction,
                             perpendicular to the visual mesh blade face after the euler rotation. -->
                        <site name="paddle_normal" pos="0 -0.01 0" size="0.005" rgba="0 0 1 0.5"/>
                      </body>
                    </body>
                  </body>
                </body>
              </body>
            </body>
          </body>
        </body>
      </body>
    </body>

    <!-- TABLE TENNIS BALL – initial pos is overridden by set_ball_state() at reset -->
    <body name="ball" pos="-1.0 0 1.5">
      <freejoint/>
      <inertial pos="0 0 0" mass="0.0027" diaginertia="0.000000216 0.000000216 0.000000216"/>
      <!-- solref: [timeconst, dampratio] – low damratio = elastic bounce -->
      <!-- solimp: [dmin, dmax, width] – high dmax = hard surface -->
      <geom name="ball_geom" type="sphere" size="0.020" material="ball_white"
            contype="1" conaffinity="1"
            solref="0.002 0.3" solimp="0.95 0.99 0.001" condim="4"
            friction="0.6 0.005 0.0001"/>
    </body>

    <!-- Cameras -->
    <camera name="main_view" pos="3 -1.5 1.5" xyaxes="0.5 0.866 0 0.354 -0.204 0.913"/>
    <camera name="side_view" pos="0 -4 1.2" xyaxes="1 0 0 0 0.3 1"/>
    <camera name="top_view" pos="0 0 5" xyaxes="1 0 0 0 1 0"/>
    <camera name="robot_view" pos="2.5 0 1.2" xyaxes="0 1 0 -0.3 0 1"/>
  </worldbody>
  
  <actuator>
    <position name="pos_joint1" joint="fr3_joint1" kp="2000" kv="80" ctrlrange="-2.9007 2.9007" forcerange="-87 87"/>
    <position name="pos_joint2" joint="fr3_joint2" kp="2000" kv="80" ctrlrange="-1.8326 1.8326" forcerange="-87 87"/>
    <position name="pos_joint3" joint="fr3_joint3" kp="2000" kv="80" ctrlrange="-2.9007 2.9007" forcerange="-87 87"/>
    <position name="pos_joint4" joint="fr3_joint4" kp="2000" kv="80" ctrlrange="-3.0718 -0.0698" forcerange="-87 87"/>
    <position name="pos_joint5" joint="fr3_joint5" kp="2000" kv="80" ctrlrange="-2.8774 2.8774" forcerange="-87 87"/>
    <position name="pos_joint6" joint="fr3_joint6" kp="2000" kv="80" ctrlrange="-0.0175 3.7525" forcerange="-87 87"/>
    <position name="pos_joint7" joint="fr3_joint7" kp="2000" kv="80" ctrlrange="-3.0543 3.0543" forcerange="-87 87"/>
    <motor name="torque_joint1" joint="fr3_joint1" gear="1" ctrlrange="-87 87" ctrllimited="true"/>
    <motor name="torque_joint2" joint="fr3_joint2" gear="1" ctrlrange="-87 87" ctrllimited="true"/>
    <motor name="torque_joint3" joint="fr3_joint3" gear="1" ctrlrange="-87 87" ctrllimited="true"/>
    <motor name="torque_joint4" joint="fr3_joint4" gear="1" ctrlrange="-87 87" ctrllimited="true"/>
    <motor name="torque_joint5" joint="fr3_joint5" gear="1" ctrlrange="-87 87" ctrllimited="true"/>
    <motor name="torque_joint6" joint="fr3_joint6" gear="1" ctrlrange="-87 87" ctrllimited="true"/>
    <motor name="torque_joint7" joint="fr3_joint7" gear="1" ctrlrange="-87 87" ctrllimited="true"/>
    <velocity name="vel_joint1" joint="fr3_joint1" kv="10" ctrlrange="-2.62 2.62" forcerange="-87 87"/>
    <velocity name="vel_joint2" joint="fr3_joint2" kv="10" ctrlrange="-2.62 2.62" forcerange="-87 87"/>
    <velocity name="vel_joint3" joint="fr3_joint3" kv="10" ctrlrange="-2.62 2.62" forcerange="-87 87"/>
    <velocity name="vel_joint4" joint="fr3_joint4" kv="10" ctrlrange="-2.62 2.62" forcerange="-87 87"/>
    <velocity name="vel_joint5" joint="fr3_joint5" kv="10" ctrlrange="-5.26 5.26" forcerange="-87 87"/>
    <velocity name="vel_joint6" joint="fr3_joint6" kv="10" ctrlrange="-4.18 4.18" forcerange="-87 87"/>
    <velocity name="vel_joint7" joint="fr3_joint7" kv="10" ctrlrange="-5.26 5.26" forcerange="-87 87"/>
  </actuator>
  
  <sensor>
    <jointpos name="joint1_pos" joint="fr3_joint1"/>
    <jointpos name="joint2_pos" joint="fr3_joint2"/>
    <jointpos name="joint3_pos" joint="fr3_joint3"/>
    <jointpos name="joint4_pos" joint="fr3_joint4"/>
    <jointpos name="joint5_pos" joint="fr3_joint5"/>
    <jointpos name="joint6_pos" joint="fr3_joint6"/>
    <jointpos name="joint7_pos" joint="fr3_joint7"/>
    <jointvel name="joint1_vel" joint="fr3_joint1"/>
    <jointvel name="joint2_vel" joint="fr3_joint2"/>
    <jointvel name="joint3_vel" joint="fr3_joint3"/>
    <jointvel name="joint4_vel" joint="fr3_joint4"/>
    <jointvel name="joint5_vel" joint="fr3_joint5"/>
    <jointvel name="joint6_vel" joint="fr3_joint6"/>
    <jointvel name="joint7_vel" joint="fr3_joint7"/>
    <framepos name="paddle_pos" objtype="site" objname="paddle_contact"/>
    <framequat name="paddle_quat" objtype="site" objname="paddle_contact"/>
    <framelinvel name="paddle_linvel" objtype="site" objname="paddle_contact"/>
    <frameangvel name="paddle_angvel" objtype="site" objname="paddle_contact"/>
    <touch name="paddle_blade_touch" site="paddle_contact"/>
    <framepos name="ball_pos" objtype="xbody" objname="ball"/>
  </sensor>
  
  <contact>
    <!-- ═══ BALL CONTACTS ═══════════════════════════════════════════════════ -->
    <!-- Ball-Table: elastic bounce (measured COR ≈ 0.58 average).
         solref[0] ≥ 5×timestep = 0.005s minimum to avoid numerical explosion.
         solref[1] = dampratio: stability boundary is 0.15 (below that the constraint
         becomes numerically unstable and COR exceeds 1.0 at low-speed impacts).
         Empirically measured effective COR with 1 ms timestep:
           damratio 0.20 → COR ≈ 0.43  (ball barely rises after 2nd bounce — too low)
           damratio 0.15 → COR ≈ 0.55 (borderline — inconsistent across bounce speeds)
           damratio 0.16 → COR ≈ 0.58  (stable, consistent; 13 cm apex after 2nd bounce)
           damratio 0.14 → solver instability (COR > 1 at lower impact speeds)
         solimp high dmax=0.999 → hard constraint, minimises penetration. -->
    <pair geom1="ball_geom" geom2="table_top"
          solref="0.005 0.16" solimp="0.97 0.999 0.001"
          friction="0.4 0.002 0.0001" condim="4"/>

    <!-- Ball-Floor: moderate bounce (COR ≈ 0.6) -->
    <pair geom1="ball_geom" geom2="floor"
          solref="0.005 0.5" solimp="0.90 0.97 0.001"
          friction="0.6 0.005 0.0001" condim="4"/>

    <!-- Ball-Paddle: rubberised surface, underdamped for good speed transfer (COR ≈ 0.8) -->
    <pair geom1="ball_geom" geom2="paddle_blade"
          solref="0.005 0.3" solimp="0.95 0.999 0.001"
          friction="0.9 0.005 0.0001" condim="4"/>

    <!-- Ball-Net: net absorbs energy (overdamped) but spring must be stiff
         enough to reverse a ~4 m/s ball within the 1 cm net thickness.
         solref[0]=0.005 (5ms) gives K≈4270 N/m → 3+ m/s impulse per step. -->
    <pair geom1="ball_geom" geom2="net_collision"
          solref="0.005 2.0" solimp="0.90 0.999 0.001"
          friction="0.3 0.005 0.0001" condim="4"/>

    <!-- ═══ PADDLE CONTACTS ═══════════════════════════════════════════════ -->
    <pair geom1="paddle_blade" geom2="table_top"  solref="0.01 0.8" solimp="0.70 0.90 0.001"/>
    <pair geom1="paddle_blade" geom2="net_collision" solref="0.01 1.0" solimp="0.70 0.90 0.001"/>

    <!-- ═══ SELF-COLLISION EXCLUDES ══════════════════════════════════════ -->
    <!-- MuJoCo auto-excludes direct parent-child pairs.                     -->
    <!-- Explicit excludes for 2-hop and 3-hop neighbours in the chain to    -->
    <!-- prevent instability from near-adjacent links briefly touching.      -->

    <!-- 2-hop pairs -->
    <exclude body1="fr3_link0" body2="fr3_link2"/>
    <exclude body1="fr3_link1" body2="fr3_link3"/>
    <exclude body1="fr3_link2" body2="fr3_link4"/>
    <exclude body1="fr3_link3" body2="fr3_link5"/>
    <exclude body1="fr3_link4" body2="fr3_link6"/>
    <exclude body1="fr3_link5" body2="fr3_link7"/>
    <exclude body1="fr3_link6" body2="fr3_link8"/>
    <exclude body1="fr3_link7" body2="paddle"/>

    <!-- 3-hop pairs -->
    <exclude body1="fr3_link0" body2="fr3_link3"/>
    <exclude body1="fr3_link1" body2="fr3_link4"/>
    <exclude body1="fr3_link2" body2="fr3_link5"/>
    <exclude body1="fr3_link3" body2="fr3_link6"/>
    <exclude body1="fr3_link4" body2="fr3_link7"/>
    <exclude body1="fr3_link5" body2="fr3_link8"/>
    <exclude body1="fr3_link6" body2="paddle"/>

    <!-- 4-hop pairs -->
    <exclude body1="fr3_link0" body2="fr3_link4"/>
    <exclude body1="fr3_link1" body2="fr3_link5"/>
    <exclude body1="fr3_link2" body2="fr3_link6"/>
    <exclude body1="fr3_link3" body2="fr3_link7"/>
    <exclude body1="fr3_link4" body2="fr3_link8"/>
    <exclude body1="fr3_link5" body2="paddle"/>
  </contact>

  <keyframe>
    <!-- ctrl order: 7 position | 7 motor | 7 velocity actuators -->
    <key name="home"  qpos="0 0 0 -1.5708 0 1.5708 0.785 0 0 0 1 0 0 0"
         ctrl="0 0 0 -1.5708 0 1.5708 0.785  0 0 0 0 0 0 0  0 0 0 0 0 0 0"/>
    <key name="ready" qpos="0 -0.5 0 -1.8 0 1.5 0.785 0 0 0 1 0 0 0"
         ctrl="0 -0.5 0 -1.8 0 1.5 0.785  0 0 0 0 0 0 0  0 0 0 0 0 0 0"/>
  </keyframe>
</mujoco>
